2021-08-06 20:44:35,532 INFO    MainThread:21476 [internal.py:wandb_internal():88] W&B internal server running at pid: 21476, started at: 2021-08-06 20:44:35.529851
2021-08-06 20:44:35,533 DEBUG   HandlerThread:21476 [handler.py:handle_request():124] handle_request: check_version
2021-08-06 20:44:35,533 INFO    WriterThread:21476 [datastore.py:open_for_write():80] open: E:\UCB\2021 Summer\GEnerative\MCR2\wandb\run-20210806_204434-76b17236\run-76b17236.wandb
2021-08-06 20:44:35,538 DEBUG   SenderThread:21476 [sender.py:send():179] send: header
2021-08-06 20:44:35,538 DEBUG   SenderThread:21476 [sender.py:send_request():193] send_request: check_version
2021-08-06 20:44:37,619 DEBUG   SenderThread:21476 [sender.py:send():179] send: run
2021-08-06 20:44:47,295 ERROR   SenderThread:21476 [retry.py:__call__():126] Retry attempt failed:
Traceback (most recent call last):
  File "C:\Users\Administrator\AppData\Local\Programs\Python\Python38\lib\site-packages\urllib3\connectionpool.py", line 696, in urlopen
    self._prepare_proxy(conn)
  File "C:\Users\Administrator\AppData\Local\Programs\Python\Python38\lib\site-packages\urllib3\connectionpool.py", line 964, in _prepare_proxy
    conn.connect()
  File "C:\Users\Administrator\AppData\Local\Programs\Python\Python38\lib\site-packages\urllib3\connection.py", line 359, in connect
    conn = self._connect_tls_proxy(hostname, conn)
  File "C:\Users\Administrator\AppData\Local\Programs\Python\Python38\lib\site-packages\urllib3\connection.py", line 500, in _connect_tls_proxy
    return ssl_wrap_socket(
  File "C:\Users\Administrator\AppData\Local\Programs\Python\Python38\lib\site-packages\urllib3\util\ssl_.py", line 449, in ssl_wrap_socket
    ssl_sock = _ssl_wrap_socket_impl(
  File "C:\Users\Administrator\AppData\Local\Programs\Python\Python38\lib\site-packages\urllib3\util\ssl_.py", line 493, in _ssl_wrap_socket_impl
    return ssl_context.wrap_socket(sock, server_hostname=server_hostname)
  File "C:\Users\Administrator\AppData\Local\Programs\Python\Python38\lib\ssl.py", line 500, in wrap_socket
    return self.sslsocket_class._create(
  File "C:\Users\Administrator\AppData\Local\Programs\Python\Python38\lib\ssl.py", line 1040, in _create
    self.do_handshake()
  File "C:\Users\Administrator\AppData\Local\Programs\Python\Python38\lib\ssl.py", line 1309, in do_handshake
    self._sslobj.do_handshake()
ssl.SSLEOFError: EOF occurred in violation of protocol (_ssl.c:1125)

During handling of the above exception, another exception occurred:

Traceback (most recent call last):
  File "C:\Users\Administrator\AppData\Local\Programs\Python\Python38\lib\site-packages\requests\adapters.py", line 439, in send
    resp = conn.urlopen(
  File "C:\Users\Administrator\AppData\Local\Programs\Python\Python38\lib\site-packages\urllib3\connectionpool.py", line 755, in urlopen
    retries = retries.increment(
  File "C:\Users\Administrator\AppData\Local\Programs\Python\Python38\lib\site-packages\urllib3\util\retry.py", line 574, in increment
    raise MaxRetryError(_pool, url, error or ResponseError(cause))
urllib3.exceptions.MaxRetryError: HTTPSConnectionPool(host='api.wandb.ai', port=443): Max retries exceeded with url: /graphql (Caused by SSLError(SSLEOFError(8, 'EOF occurred in violation of protocol (_ssl.c:1125)')))

During handling of the above exception, another exception occurred:

Traceback (most recent call last):
  File "C:\Users\Administrator\AppData\Local\Programs\Python\Python38\lib\site-packages\wandb\sdk\lib\retry.py", line 102, in __call__
    result = self._call_fn(*args, **kwargs)
  File "C:\Users\Administrator\AppData\Local\Programs\Python\Python38\lib\site-packages\wandb\sdk\internal\internal_api.py", line 130, in execute
    return self.client.execute(*args, **kwargs)
  File "C:\Users\Administrator\AppData\Local\Programs\Python\Python38\lib\site-packages\wandb\vendor\gql-0.2.0\gql\client.py", line 52, in execute
    result = self._get_result(document, *args, **kwargs)
  File "C:\Users\Administrator\AppData\Local\Programs\Python\Python38\lib\site-packages\wandb\vendor\gql-0.2.0\gql\client.py", line 60, in _get_result
    return self.transport.execute(document, *args, **kwargs)
  File "C:\Users\Administrator\AppData\Local\Programs\Python\Python38\lib\site-packages\wandb\vendor\gql-0.2.0\gql\transport\requests.py", line 38, in execute
    request = requests.post(self.url, **post_args)
  File "C:\Users\Administrator\AppData\Local\Programs\Python\Python38\lib\site-packages\requests\api.py", line 119, in post
    return request('post', url, data=data, json=json, **kwargs)
  File "C:\Users\Administrator\AppData\Local\Programs\Python\Python38\lib\site-packages\requests\api.py", line 61, in request
    return session.request(method=method, url=url, **kwargs)
  File "C:\Users\Administrator\AppData\Local\Programs\Python\Python38\lib\site-packages\requests\sessions.py", line 542, in request
    resp = self.send(prep, **send_kwargs)
  File "C:\Users\Administrator\AppData\Local\Programs\Python\Python38\lib\site-packages\requests\sessions.py", line 655, in send
    r = adapter.send(request, **kwargs)
  File "C:\Users\Administrator\AppData\Local\Programs\Python\Python38\lib\site-packages\requests\adapters.py", line 514, in send
    raise SSLError(e, request=request)
requests.exceptions.SSLError: HTTPSConnectionPool(host='api.wandb.ai', port=443): Max retries exceeded with url: /graphql (Caused by SSLError(SSLEOFError(8, 'EOF occurred in violation of protocol (_ssl.c:1125)')))
2021-08-06 20:45:07,631 DEBUG   HandlerThread:21476 [handler.py:handle_request():124] handle_request: shutdown
2021-08-06 20:45:07,631 INFO    HandlerThread:21476 [handler.py:finish():658] shutting down handler
2021-08-06 20:45:07,837 INFO    WriterThread:21476 [datastore.py:close():288] close: E:\UCB\2021 Summer\GEnerative\MCR2\wandb\run-20210806_204434-76b17236\run-76b17236.wandb
